Workbook

Sheet MPsizeBase+parameters
A1: FROM MPSIZEBASE | H1: INFO SAMPLING | J1: FROM MARTIN DATASET | O1: NOT FROM MARTIN | Q1: MASS IN g/cm2 | T1: COMPUTED USING MARIN DATA | W1: COMPUTED USING RESTREPPO DATA | Z1: EXTRAPOLATED TO 2021 | AC1: COMPARISON
A2: PSD ID | B2: Lat | C2: Lon | D2: Shape | E2: Info shape | F2: Slope | G2: MP mass observation extrapolated to 1-5000 µm (µg/kg) from MPsizeBase | H2: year of sampling | I2: thickness of the sampled sediment layer (cm) | J2: reference numbrer in Martin dataset | K2: Distance_land (m) Martin dataset | L2: Water_Depth (m) Martin dataset | M2: Dry bulk density of the sediments (g/cm³) Martin dataset | N2: accumulation rate (cm/yr) Martin dataset | O2: Accumulation rate from Restreppo | P2: Distance to land NASA Ocean Biology Processing Group (m) | Q2: mass converted to g/cm³ | R2: mass converted to g/cm² | S2: accumulation time (yr) since 1950 | T2: time represented by the sampled sediment layer (yr) | U2: total thickness of the sediments (cm) since 1950 | V2: MP stock (g/m2) in year of study | W2: time represented by the sampled sediment layer (yr) | X2: total thickness of the sediments (cm) since 1950 | Y2: MP stock (g/m2) in year of study | Z2: accumulation time (yr) since 1950 | AA2: parameter a | AB2: MP stock (g/m2) in 2021 | AC2: Difference | AD2: % Difference
A3: Wan19a_A_1 | B3: 33 | C3: 122.21 | D3: Fibers | E3: 0.91 | F3: -1.28 | G3: 28.4 | H3: 2017 | I3: 3 | J3: 1 | K3: 112.65408 | L3: 12 | M3: 0.61037441 | N3: 0.13182412 | O3: 0.33732978 | P3: 104000 | Q3: =G3*M3*0.000000001 -> 1.7334633e-08 | R3: =Q3*I3 -> 5.20039e-08 | S3: =H3-1950 -> 67 | T3: =I3/N3 -> 22.757595 | U3: =N3*S3 -> 8.8322162 | V3: =IF(I3<U3,R3/(1-(1-I3/U3)^3),R3)*10000 -> 0.00073032335 | W3: =I3/O3 -> 8.8933743 | X3: =O3*S3 -> 22.601095 | Y3: =IF(I3<X3,R3/(1-(1-I3/X3)^3),R3)*10000 -> 0.0014956878 | Z3: =2021-1950 -> 71 | AA3: {=_xlfn.IFS(I3<=X3,R3*(3/(S3^3 - (S3-W3)^3)),I3>X3,R3*(3/S3^3))} -> 1.4918934e-12 | AB3: =(AA3/3)*(Z3^3)*10000 -> 0.0017798835 | AC3: =Y3-AB3 -> -0.00028419575 | AD3: =AB3*100/Y3 -> 119.00101
A4: Wan19a_A_2 | B4: 34 | C4: 121.24 | D4: Fibers | E4: 0.96 | F4: -1.65 | G4: 111 | H4: 2017 | I4: 3 | J4: 1 | K4: 96.56064 | L4: 19 | M4: 0.61037441 | N4: 0.13090283 | O4: 0.82634632 | P4: 73000 | Q4: =G4*M4*0.000000001 -> 6.7751559e-08 | R4: =Q4*I4 -> 2.0325468e-07 | S4: =H4-1950 -> 67 | T4: =I4/N4 -> 22.917762 | U4: =N4*S4 -> 8.7704899 | V4: =IF(I4<U4,R4/(1-(1-I4/U4)^3),R4)*10000 -> 0.0028419969 | W4: =I4/O4 -> 3.6304391 | X4: =O4*S4 -> 55.365204 | Y4: =IF(I4<X4,R4/(1-(1-I4/X4)^3),R4)*10000 -> 0.013206261 | Z4: =2021-1950 -> 71 | AA4: {=_xlfn.IFS(I4<=X4,R4*(3/(S4^3 - (S4-W4)^3)),I4>X4,R4*(3/S4^3))} -> 1.3172759e-11 | AB4: =(AA4/3)*(Z4^3)*10000 -> 0.015715584 | AC4: =Y4-AB4 -> -0.0025093227 | AD4: =AB4*100/Y4 -> 119.00101
A5: Wan19a_A_3 | B5: 36 | C5: 121 | D5: Fibers | E5: 0.96 | F5: -1.35 | G5: 180 | H5: 2017 | I5: 3 | J5: 1 | K5: 32.18688 | L5: 20 | M5: 0.61037441 | N5: 0.13077175 | O5: 0.23090016 | P5: 16000 | Q5: =G5*M5*0.000000001 -> 1.0986739e-07 | R5: =Q5*I5 -> 3.2960218e-07 | S5: =H5-1950 -> 67 | T5: =I5/N5 -> 22.940735 | U5: =N5*S5 -> 8.7617071 | V5: =IF(I5<U5,R5/(1-(1-I5/U5)^3),R5)*10000 -> 0.0046057775 | W5: =I5/O5 -> 12.992628 | X5: =O5*S5 -> 15.470311 | Y5: =IF(I5<X5,R5/(1-(1-I5/X5)^3),R5)*10000 -> 0.006920968 | Z5: =2021-1950 -> 71 | AA5: {=_xlfn.IFS(I5<=X5,R5*(3/(S5^3 - (S5-W5)^3)),I5>X5,R5*(3/S5^3))} -> 6.9034103e-12 | AB5: =(AA5/3)*(Z5^3)*10000 -> 0.0082360216 | AC5: =Y5-AB5 -> -0.0013150536 | AD5: =AB5*100/Y5 -> 119.00101
A6: Wan19a_A_4 | B6: 33 | C6: 123 | D6: Fibers | E6: 0.81 | F6: -1.47 | G6: 74.8 | H6: 2017 | I6: 3 | J6: 1 | K6: 160.9344 | L6: 29 | M6: 0.61037441 | N6: 0.12959787 | O6: 0.41044832 | P6: 161000 | Q6: =G6*M6*0.000000001 -> 4.5656006e-08 | R6: =Q6*I6 -> 1.3696802e-07 | S6: =H6-1950 -> 67 | T6: =I6/N6 -> 23.148529 | U6: =N6*S6 -> 8.683057 | V6: =IF(I6<U6,R6/(1-(1-I6/U6)^3),R6)*10000 -> 0.0019033058 | W6: =I6/O6 -> 7.309081 | X6: =O6*S6 -> 27.500037 | Y6: =IF(I6<X6,R6/(1-(1-I6/X6)^3),R6)*10000 -> 0.0046767806 | Z6: =2021-1950 -> 71 | AA6: {=_xlfn.IFS(I6<=X6,R6*(3/(S6^3 - (S6-W6)^3)),I6>X6,R6*(3/S6^3))} -> 4.6649162e-12 | AB6: =(AA6/3)*(Z6^3)*10000 -> 0.0055654161 | AC6: =Y6-AB6 -> -0.00088863544 | AD6: =AB6*100/Y6 -> 119.00101
A7: Wan19a_A_5 | B7: 35 | C7: 121.39 | D7: Fibers | E7: 0.91 | F7: -1.67 | G7: 81.9 | H7: 2017 | I7: 3 | J7: 1 | K7: 144.84096 | L7: 36 | M7: 0.61037441 | N7: 0.12869214 | O7: 0.14227124 | P7: 110000 | Q7: =G7*M7*0.000000001 -> 4.9989664e-08 | R7: =Q7*I7 -> 1.4996899e-07 | S7: =H7-1950 -> 67 | T7: =I7/N7 -> 23.311448 | U7: =N7*S7 -> 8.6223731 | V7: =IF(I7<U7,R7/(1-(1-I7/U7)^3),R7)*10000 -> 0.0020749902 | W7: =I7/O7 -> 21.086482 | X7: =O7*S7 -> 9.5321732 | Y7: =IF(I7<X7,R7/(1-(1-I7/X7)^3),R7)*10000 -> 0.0022113069 | Z7: =2021-1950 -> 71 | AA7: {=_xlfn.IFS(I7<=X7,R7*(3/(S7^3 - (S7-W7)^3)),I7>X7,R7*(3/S7^3))} -> 2.2056971e-12 | AB7: =(AA7/3)*(Z7^3)*10000 -> 0.0026314775 | AC7: =Y7-AB7 -> -0.0004201706 | AD7: =AB7*100/Y7 -> 119.00101
A8: Wan19a_A_6 | B8: 36 | C8: 121.4 | D8: Fibers | E8: 0.86 | F8: -1.19 | G8: 108 | H8: 2017 | I8: 3 | J8: 1 | K8: 80.4672 | L8: 36 | M8: 0.61037441 | N8: 0.12869214 | O8: 0.14468963 | P8: 48000 | Q8: =G8*M8*0.000000001 -> 6.5920436e-08 | R8: =Q8*I8 -> 1.9776131e-07 | S8: =H8-1950 -> 67 | T8: =I8/N8 -> 23.311448 | U8: =N8*S8 -> 8.6223731 | V8: =IF(I8<U8,R8/(1-(1-I8/U8)^3),R8)*10000 -> 0.0027362509 | W8: =I8/O8 -> 20.734036 | X8: =O8*S8 -> 9.6942052 | Y8: =IF(I8<X8,R8/(1-(1-I8/X8)^3),R8)*10000 -> 0.0029484764 | Z8: =2021-1950 -> 71 | AA8: {=_xlfn.IFS(I8<=X8,R8*(3/(S8^3 - (S8-W8)^3)),I8>X8,R8*(3/S8^3))} -> 2.9409965e-12 | AB8: =(AA8/3)*(Z8^3)*10000 -> 0.0035087166 | AC8: =Y8-AB8 -> -0.00056024022 | AD8: =AB8*100/Y8 -> 119.00101
A9: Wan19a_A_7 | B9: 35 | C9: 123 | D9: Fibers | E9: 0.84 | F9: -1.69 | G9: 114 | H9: 2017 | I9: 3 | J9: 1 | K9: 209.21472 | L9: 45 | M9: 0.61037441 | N9: 0.12753692 | O9: 0.1410178 | P9: 202000 | Q9: =G9*M9*0.000000001 -> 6.9582683e-08 | R9: =Q9*I9 -> 2.0874805e-07 | S9: =H9-1950 -> 67 | T9: =I9/N9 -> 23.5226 | U9: =N9*S9 -> 8.5449737 | V9: =IF(I9<U9,R9/(1-(1-I9/U9)^3),R9)*10000 -> 0.0028723654 | W9: =I9/O9 -> 21.27391 | X9: =O9*S9 -> 9.4481925 | Y9: =IF(I9<X9,R9/(1-(1-I9/X9)^3),R9)*10000 -> 0.0030602984 | Z9: =2021-1950 -> 71 | AA9: {=_xlfn.IFS(I9<=X9,R9*(3/(S9^3 - (S9-W9)^3)),I9>X9,R9*(3/S9^3))} -> 3.0525348e-12 | AB9: =(AA9/3)*(Z9^3)*10000 -> 0.0036417859 | AC9: =Y9-AB9 -> -0.00058148753 | AD9: =AB9*100/Y9 -> 119.00101
A10: Wan19a_A_8 | B10: 34 | C10: 124 | D10: Fibers | E10: 0.85 | F10: -1.67 | G10: 90.9 | H10: 2017 | I10: 3 | J10: 1 | K10: 209.21472 | L10: 50 | M10: 0.61037441 | N10: 0.12689962 | O10: 0.34369892 | P10: 100000 | Q10: =G10*M10*0.000000001 -> 5.5483034e-08 | R10: =Q10*I10 -> 1.664491e-07 | S10: =H10-1950 -> 67 | T10: =I10/N10 -> 23.640732 | U10: =N10*S10 -> 8.5022747 | V10: =IF(I10<U10,R10/(1-(1-I10/U10)^3),R10)*10000 -> 0.0022833543 | W10: =I10/O10 -> 8.7285697 | X10: =O10*S10 -> 23.027828 | Y10: =IF(I10<X10,R10/(1-(1-I10/X10)^3),R10)*10000 -> 0.0048651383 | Z10: =2021-1950 -> 71 | AA10: {=_xlfn.IFS(I10<=X10,R10*(3/(S10^3 - (S10-W10)^3)),I10>X10,R10*(3/S10^3))} -> 4.852796e-12 | AB10: =(AA10/3)*(Z10^3)*10000 -> 0.0057895636 | AC10: =Y10-AB10 -> -0.00092442529 | AD10: =AB10*100/Y10 -> 119.00101
A11: Wan19a_A_9 | B11: 36 | C11: 122 | D11: Fibers | E11: 0.74 | F11: -1.66 | G11: 83.2 | H11: 2017 | I11: 3 | J11: 1 | K11: 96.56064 | L11: 50 | M11: 0.61037441 | N11: 0.12689962 | O11: 0.14041207 | P11: 87000 | Q11: =G11*M11*0.000000001 -> 5.0783151e-08 | R11: =Q11*I11 -> 1.5234945e-07 | S11: =H11-1950 -> 67 | T11: =I11/N11 -> 23.640732 | U11: =N11*S11 -> 8.5022747 | V11: =IF(I11<U11,R11/(1-(1-I11/U11)^3),R11)*10000 -> 0.0020899348 | W11: =I11/O11 -> 21.365685 | X11: =O11*S11 -> 9.4076085 | Y11: =IF(I11<X11,R11/(1-(1-I11/X11)^3),R11)*10000 -> 0.0022272438 | Z11: =2021-1950 -> 71 | AA11: {=_xlfn.IFS(I11<=X11,R11*(3/(S11^3 - (S11-W11)^3)),I11>X11,R11*(3/S11^3))} -> 2.2215935e-12 | AB11: =(AA11/3)*(Z11^3)*10000 -> 0.0026504425 | AC11: =Y11-AB11 -> -0.00042319876 | AD11: =AB11*100/Y11 -> 119.00101
A12: Wan19a_A_10 | B12: 35 | C12: 124 | D12: Fibers | E12: 0.67 | F12: -1.65 | G12: 77.4 | H12: 2017 | I12: 3 | J12: 1 | K12: 193.12128 | L12: 64 | M12: 0.61037441 | N12: 0.12513208 | O12: 0.14089302 | P12: 113000 | Q12: =G12*M12*0.000000001 -> 4.7242979e-08 | R12: =Q12*I12 -> 1.4172894e-07 | S12: =H12-1950 -> 67 | T12: =I12/N12 -> 23.974668 | U12: =N12*S12 -> 8.3838491 | V12: =IF(I12<U12,R12/(1-(1-I12/U12)^3),R12)*10000 -> 0.0019278087 | W12: =I12/O12 -> 21.292751 | X12: =O12*S12 -> 9.4398324 | Y12: =IF(I12<X12,R12/(1-(1-I12/X12)^3),R12)*10000 -> 0.0020765858 | Z12: =2021-1950 -> 71 | AA12: {=_xlfn.IFS(I12<=X12,R12*(3/(S12^3 - (S12-W12)^3)),I12>X12,R12*(3/S12^3))} -> 2.0713178e-12 | AB12: =(AA12/3)*(Z12^3)*10000 -> 0.002471158 | AC12: =Y12-AB12 -> -0.00039457222 | AD12: =AB12*100/Y12 -> 119.00101
A13: Wan19a_A_11 | B13: 36 | C13: 123 | D13: Fibers | E13: 0.82 | F13: -1.61 | G13: 94.9 | H13: 2017 | I13: 3 | J13: 1 | K13: 112.65408 | L13: 70 | M13: 0.61037441 | N13: 0.12438211 | O13: 0.13914418 | P13: 107000 | Q13: =G13*M13*0.000000001 -> 5.7924531e-08 | R13: =Q13*I13 -> 1.7377359e-07 | S13: =H13-1950 -> 67 | T13: =I13/N13 -> 24.119224 | U13: =N13*S13 -> 8.3336016 | V13: =IF(I13<U13,R13/(1-(1-I13/U13)^3),R13)*10000 -> 0.0023551607 | W13: =I13/O13 -> 21.56037 | X13: =O13*S13 -> 9.32266 | Y13: =IF(I13<X13,R13/(1-(1-I13/X13)^3),R13)*10000 -> 0.0025255821 | Z13: =2021-1950 -> 71 | AA13: {=_xlfn.IFS(I13<=X13,R13*(3/(S13^3 - (S13-W13)^3)),I13>X13,R13*(3/S13^3))} -> 2.519175e-12 | AB13: =(AA13/3)*(Z13^3)*10000 -> 0.0030054682 | AC13: =Y13-AB13 -> -0.00047988605 | AD13: =AB13*100/Y13 -> 119.00101
A14: Wan19a_A_12 | B14: 35 | C14: 124 | D14: Fibers | E14: 0.67 | F14: -1.69 | G14: 135 | H14: 2017 | I14: 3 | J14: 1 | K14: 193.12128 | L14: 72 | M14: 0.61037441 | N14: 0.12413313 | O14: 0.14089302 | P14: 113000 | Q14: =G14*M14*0.000000001 -> 8.2400545e-08 | R14: =Q14*I14 -> 2.4720164e-07 | S14: =H14-1950 -> 67 | T14: =I14/N14 -> 24.167602 | U14: =N14*S14 -> 8.3169194 | V14: =IF(I14<U14,R14/(1-(1-I14/U14)^3),R14)*10000 -> 0.0033463144 | W14: =I14/O14 -> 21.292751 | X14: =O14*S14 -> 9.4398324 | Y14: =IF(I14<X14,R14/(1-(1-I14/X14)^3),R14)*10000 -> 0.003621952 | Z14: =2021-1950 -> 71 | AA14: {=_xlfn.IFS(I14<=X14,R14*(3/(S14^3 - (S14-W14)^3)),I14>X14,R14*(3/S14^3))} -> 3.6127635e-12 | AB14: =(AA14/3)*(Z14^3)*10000 -> 0.0043101594 | AC14: =Y14-AB14 -> -0.00068820737 | AD14: =AB14*100/Y14 -> 119.00101
... A16: Wan19a_A_14 | B16: 32.3 | C16: 122.12 | D16: Fibers | E16: 0.8797 | F16: -1.43 | G16: 38 | H16: 2017 | I16: 3 | J16: 1 | K16: 80.4672 | L16: 26 | M16: 0.61037441 | N16: 0.09181562 | O16: 1.9778785 | P16: 48000 | Q16: =G16*M16*0.000000001 -> 2.3194228e-08 | R16: =Q16*I16 -> 6.9582683e-08 | S16: =H16-1950 -> 67 | T16: =I16/N16 -> 32.674179 | U16: =N16*S16 -> 6.1516465 | V16: =IF(I16<U16,R16/(1-(1-I16/U16)^3),R16)*10000 -> 0.00080393523 | W16: =I16/O16 -> 1.5167767 | X16: =O16*S16 -> 132.51786 | Y16: =IF(I16<X16,R16/(1-(1-I16/X16)^3),R16)*10000 -> 0.010480981 | Z16: =2021-1950 -> 71 | AA16: {=_xlfn.IFS(I16<=X16,R16*(3/(S16^3 - (S16-W16)^3)),I16>X16,R16*(3/S16^3))} -> 1.0454392e-11 | AB16: =(AA16/3)*(Z16^3)*10000 -> 0.012472473 | AC16: =Y16-AB16 -> -0.001991492 | AD16: =AB16*100/Y16 -> 119.00101
A17: Mu19_A_1 | B17: 66 | C17: -168 | D17: Fibers | E17: 64% fibers | F17: -1.22 | G17: 1.31 | H17: 2017 | I17: 5 | J17: 2 | K17: 155053.86 | L17: 71.16 | M17: 0.81517199 | N17: 0.12429491 | O17: 0.063551595 | P17: 27000 | Q17: =G17*M17*0.000000001 -> 1.0678753e-09 | R17: =Q17*I17 -> 5.3393765e-09 | S17: =H17-1950 -> 67 | T17: =I17/N17 -> 40.22691 | U17: =N17*S17 -> 8.3277587 | V17: =IF(I17<U17,R17/(1-(1-I17/U17)^3),R17)*10000 -> 5.7032886e-05 | W17: =I17/O17 -> 78.676232 | X17: =O17*S17 -> 4.2579569 | Y17: =IF(I17<X17,R17/(1-(1-I17/X17)^3),R17)*10000 -> 5.3393765e-05 | Z17: =2021-1950 -> 71 | AA17: {=_xlfn.IFS(I17<=X17,R17*(3/(S17^3 - (S17-W17)^3)),I17>X17,R17*(3/S17^3))} -> 5.3258312e-14 | AB17: =(AA17/3)*(Z17^3)*10000 -> 6.3539119e-05 | AC17: =Y17-AB17 -> -1.0145353e-05 | AD17: =AB17*100/Y17 -> 119.00101
A18: Alv20_A_1 | B18: 31.82 | C18: -116.72 | D18: Fibers | E18: 100% fibers | F18: -2.16 | G18: 27.7 | H18: 2016 | I18: 5 | J18: 74 | K18: 4912.5226 | L18: 72.416667 | M18: 0.49520066 | N18: 0.13261896 | O18: 0.18873249 | P18: 5000 | Q18: =G18*M18*0.000000001 -> 1.3717058e-08 | R18: =Q18*I18 -> 6.8585291e-08 | S18: =H18-1950 -> 66 | T18: =I18/N18 -> 37.702 | U18: =N18*S18 -> 8.7528512 | V18: =IF(I18<U18,R18/(1-(1-I18/U18)^3),R18)*10000 -> 0.0007445372 | W18: =I18/O18 -> 26.492524 | X18: =O18*S18 -> 12.456344 | Y18: =IF(I18<X18,R18/(1-(1-I18/X18)^3),R18)*10000 -> 0.00087313016 | Z18: =2021-1950 -> 71 | AA18: {=_xlfn.IFS(I18<=X18,R18*(3/(S18^3 - (S18-W18)^3)),I18>X18,R18*(3/S18^3))} -> 9.1110502e-13 | AB18: =(AA18/3)*(Z18^3)*10000 -> 0.0010869817 | AC18: =Y18-AB18 -> -0.00021385153 | AD18: =AB18*100/Y18 -> 124.49251
A19: Alv20_A_2 | B19: 31.82 | C19: -116.72 | D19: Fragments | E19: 100% fragments | F19: -3.83 | G19: 495 | H19: 2016 | I19: 5 | J19: 74 | K19: 4912.5226 | L19: 72.416667 | M19: 0.49520066 | N19: 0.13261896 | O19: 0.18873249 | P19: 5000 | Q19: =G19*M19*0.000000001 -> 2.4512433e-07 | R19: =Q19*I19 -> 1.2256216e-06 | S19: =H19-1950 -> 66 | T19: =I19/N19 -> 37.702 | U19: =N19*S19 -> 8.7528512 | V19: =IF(I19<U19,R19/(1-(1-I19/U19)^3),R19)*10000 -> 0.013304907 | W19: =I19/O19 -> 26.492524 | X19: =O19*S19 -> 12.456344 | Y19: =IF(I19<X19,R19/(1-(1-I19/X19)^3),R19)*10000 -> 0.015602868 | Z19: =2021-1950 -> 71 | AA19: {=_xlfn.IFS(I19<=X19,R19*(3/(S19^3 - (S19-W19)^3)),I19>X19,R19*(3/S19^3))} -> 1.628148e-11 | AB19: =(AA19/3)*(Z19^3)*10000 -> 0.019424402 | AC19: =Y19-AB19 -> -0.0038215346 | AD19: =AB19*100/Y19 -> 124.49251
A20: Zha20_A_1 | B20: 30.45 | C20: 122.45 | D20: Fibers | E20: 92% fibers | F20: -1.27 | G20: 3.56 | H20: 2018 | I20: 5 | J20: 75 | K20: 50416.724 | L20: 21.65 | M20: 0.61037441 | N20: 0.1310078 | O20: 1.0224486 | P20: 1000 | Q20: =G20*M20*0.000000001 -> 2.1729329e-09 | R20: =Q20*I20 -> 1.0864664e-08 | S20: =H20-1950 -> 68 | T20: =I20/N20 -> 38.165667 | U20: =N20*S20 -> 8.9085302 | V20: =IF(I20<U20,R20/(1-(1-I20/U20)^3),R20)*10000 -> 0.00011866874 | W20: =I20/O20 -> 4.8902215 | X20: =O20*S20 -> 69.526503 | Y20: =IF(I20<X20,R20/(1-(1-I20/X20)^3),R20)*10000 -> 0.00054160386 | Z20: =2021-1950 -> 71 | AA20: {=_xlfn.IFS(I20<=X20,R20*(3/(S20^3 - (S20-W20)^3)),I20>X20,R20*(3/S20^3))} -> 5.1674498e-13 | AB20: =(AA20/3)*(Z20^3)*10000 -> 0.00061649571 | AC20: =Y20-AB20 -> -7.489185e-05 | AD20: =AB20*100/Y20 -> 113.82779
A21: Hua20_A_1 | B21: 18.407564 | C21: 109.98518 | D21: Fibers | E21: 68% fibers | F21: -1.8 | G21: 2.12 | H21: 2018 | I21: 5 | J21: 76 | K21: 160.9344 | L21: 4.2 | M21: 1.3837436 | N21: 0.13285834 | O21: 0.54845273 | P21: 1000 | Q21: =G21*M21*0.000000001 -> 2.9335363e-09 | R21: =Q21*I21 -> 1.4667682e-08 | S21: =H21-1950 -> 68 | T21: =I21/N21 -> 37.634069 | U21: =N21*S21 -> 9.0343672 | V21: =IF(I21<U21,R21/(1-(1-I21/U21)^3),R21)*10000 -> 0.00016101519 | W21: =I21/O21 -> 9.116556 | X21: =O21*S21 -> 37.294785 | Y21: =IF(I21<X21,R21/(1-(1-I21/X21)^3),R21)*10000 -> 0.00041825346 | Z21: =2021-1950 -> 71 | AA21: {=_xlfn.IFS(I21<=X21,R21*(3/(S21^3 - (S21-W21)^3)),I21>X21,R21*(3/S21^3))} -> 3.9905619e-13 | AB21: =(AA21/3)*(Z21^3)*10000 -> 0.00047608867 | AC21: =Y21-AB21 -> -5.7835214e-05 | AD21: =AB21*100/Y21 -> 113.82779
A22: Hua20_A_2 | B22: 18.407564 | C22: 109.98518 | D22: Fibers | E22: 56% fibers | F22: -2.11 | G22: 9.7 | H22: 2018 | I22: 5 | J22: 76 | K22: 144.84096 | L22: 4.2 | M22: 1.6589305 | N22: 0.2027 | O22: 0.54845273 | P22: 1000 | Q22: =G22*M22*0.000000001 -> 1.6091626e-08 | R22: =Q22*I22 -> 8.0458129e-08 | S22: =H22-1950 -> 68 | T22: =I22/N22 -> 24.666996 | U22: =N22*S22 -> 13.7836 | V22: =IF(I22<U22,R22/(1-(1-I22/U22)^3),R22)*10000 -> 0.0010854815 | W22: =I22/O22 -> 9.116556 | X22: =O22*S22 -> 37.294785 | Y22: =IF(I22<X22,R22/(1-(1-I22/X22)^3),R22)*10000 -> 0.0022942883 | Z22: =2021-1950 -> 71 | AA22: {=_xlfn.IFS(I22<=X22,R22*(3/(S22^3 - (S22-W22)^3)),I22>X22,R22*(3/S22^3))} -> 2.1889836e-12 | AB22: =(AA22/3)*(Z22^3)*10000 -> 0.0026115377 | AC22: =Y22-AB22 -> -0.00031724939 | AD22: =AB22*100/Y22 -> 113.82779
A23: Hua20_A_3 | B23: 18.415724 | C23: 110.05434 | D23: Fibers | E23: 71% fibers | F23: -1.22 | G23: 98.2 | H23: 2018 | I23: 5 | J23: 76 | K23: 241.4016 | L23: 5.5 | M23: 1.3837436 | N23: 0.13285834 | O23: 0.25807987 | P23: 1000 | Q23: =G23*M23*0.000000001 -> 1.3588362e-07 | R23: =Q23*I23 -> 6.7941809e-07 | S23: =H23-1950 -> 68 | T23: =I23/N23 -> 37.634069 | U23: =N23*S23 -> 9.0343672 | V23: =IF(I23<U23,R23/(1-(1-I23/U23)^3),R23)*10000 -> 0.0074583452 | W23: =I23/O23 -> 19.373847 | X23: =O23*S23 -> 17.549431 | Y23: =IF(I23<X23,R23/(1-(1-I23/X23)^3),R23)*10000 -> 0.010710708 | Z23: =2021-1950 -> 71 | AA23: {=_xlfn.IFS(I23<=X23,R23*(3/(S23^3 - (S23-W23)^3)),I23>X23,R23*(3/S23^3))} -> 1.0219101e-11 | AB23: =(AA23/3)*(Z23^3)*10000 -> 0.012191763 | AC23: =Y23-AB23 -> -0.0014810544 | AD23: =AB23*100/Y23 -> 113.82779
A24: Hua20_A_4 | B24: 18.415724 | C24: 110.05434 | D24: Fragments | E24: 61% fragments | F24: -1.59 | G24: 2060 | H24: 2018 | I24: 5 | J24: 76 | K24: 257.49504 | L24: 5.5 | M24: 1.6589305 | N24: 0.2027 | O24: 0.25807987 | P24: 1000 | Q24: =G24*M24*0.000000001 -> 3.4173968e-06 | R24: =Q24*I24 -> 1.7086984e-05 | S24: =H24-1950 -> 68 | T24: =I24/N24 -> 24.666996 | U24: =N24*S24 -> 13.7836 | V24: =IF(I24<U24,R24/(1-(1-I24/U24)^3),R24)*10000 -> 0.23052494 | W24: =I24/O24 -> 19.373847 | X24: =O24*S24 -> 17.549431 | Y24: =IF(I24<X24,R24/(1-(1-I24/X24)^3),R24)*10000 -> 0.26936831 | Z24: =2021-1950 -> 71 | AA24: {=_xlfn.IFS(I24<=X24,R24*(3/(S24^3 - (S24-W24)^3)),I24>X24,R24*(3/S24^3))} -> 2.5700467e-10 | AB24: =(AA24/3)*(Z24^3)*10000 -> 0.306616 | AC24: =Y24-AB24 -> -0.037247687 | AD24: =AB24*100/Y24 -> 113.82779
A25: Alv19_A_1 | B25: -22.84 | C25: -43.16 | D25: Fibers | E25: 81% fibers | F25: -2.67 | G25: 6470 | H25: 2017 | I25: 5 | J25: 84 | K25: 2321.4787 | L25: 0 | M25: 1.3738833 | N25: 0.13341858 | O25: 0.89874914 | P25: 2000 | Q25: =G25*M25*0.000000001 -> 8.8890248e-06 | R25: =Q25*I25 -> 4.4445124e-05 | S25: =H25-1950 -> 67 | T25: =I25/N25 -> 37.476038 | U25: =N25*S25 -> 8.9390452 | V25: =IF(I25<U25,R25/(1-(1-I25/U25)^3),R25)*10000 -> 0.48603953 | W25: =I25/O25 -> 5.5632877 | X25: =O25*S25 -> 60.216192 | Y25: =IF(I25<X25,R25/(1-(1-I25/X25)^3),R25)*10000 -> 1.9409121 | Z25: =2021-1950 -> 71 | AA25: {=_xlfn.IFS(I25<=X25,R25*(3/(S25^3 - (S25-W25)^3)),I25>X25,R25*(3/S25^3))} -> 1.9359882e-09 | AB25: =(AA25/3)*(Z25^3)*10000 -> 2.3097049 | AC25: =Y25-AB25 -> -0.36879285 | AD25: =AB25*100/Y25 -> 119.00101
A26: Haa19_A_1 | B26: 60.435399 | C26: 5.257967 | D26: Fragments | E26: no | F26: -2.62 | G26: 512000 | H26: 2015 | I26: 1 | J26: 72 | K26: =J26*1609.344 -> 115872.77 | L26: 333 | M26: 3.4884441 | N26: 0.095569952 | O26: 0.072594822 | P26: 1000 | Q26: =G26*M26*0.000000001 -> 0.0017860834 | R26: =Q26*I26 -> 0.0017860834 | S26: =H26-1950 -> 65 | T26: =I26/N26 -> 10.46354 | U26: =N26*S26 -> 6.2120469 | V26: =IF(I26<U26,R26/(1-(1-I26/U26)^3),R26)*10000 -> 43.630814 | W26: =I26/O26 -> 13.775087 | X26: =O26*S26 -> 4.7186635 | Y26: =IF(I26<X26,R26/(1-(1-I26/X26)^3),R26)*10000 -> 34.983151 | Z26: =2021-1950 -> 71 | AA26: {=_xlfn.IFS(I26<=X26,R26*(3/(S26^3 - (S26-W26)^3)),I26>X26,R26*(3/S26^3))} -> 3.821555e-08 | AB26: =(AA26/3)*(Z26^3)*10000 -> 45.592552 | AC26: =Y26-AB26 -> -10.609401 | AD26: =AB26*100/Y26 -> 130.32717
A27: Haa19_A_2 | B27: 60.397097 | C27: 5.2166774 | D27: Fragments | E27: no | F27: -2.67 | G27: 62400 | H27: 2015 | I27: 1 | J27: 72 | K27: =J27*1609.344 -> 115872.77 | L27: 322 | M27: 3.4884441 | N27: 0.096629046 | O27: 0.072594822 | P27: land | Q27: =G27*M27*0.000000001 -> 0.00021767891 | R27: =Q27*I27 -> 0.00021767891 | S27: =H27-1950 -> 65 | T27: =I27/N27 -> 10.348855 | U27: =N27*S27 -> 6.280888 | V27: =IF(I27<U27,R27/(1-(1-I27/U27)^3),R27)*10000 -> 5.3664554 | W27: =I27/O27 -> 13.775087 | X27: =O27*S27 -> 4.7186635 | Y27: =IF(I27<X27,R27/(1-(1-I27/X27)^3),R27)*10000 -> 4.2635716 | Z27: =2021-1950 -> 71 | AA27: {=_xlfn.IFS(I27<=X27,R27*(3/(S27^3 - (S27-W27)^3)),I27>X27,R27*(3/S27^3))} -> 4.6575202e-09 | AB27: =(AA27/3)*(Z27^3)*10000 -> 5.5565923 | AC27: =Y27-AB27 -> -1.2930207 | AD27: =AB27*100/Y27 -> 130.32717
A28: Haa19_A_3 | B28: 60.47975 | C28: 5.2385479 | D28: Fragments | E28: no | F28: -3.3 | G28: 39000 | H28: 2015 | I28: 1 | J28: 72 | K28: =J28*1609.344 -> 115872.77 | L28: 315 | M28: 3.4884441 | N28: 0.097309117 | O28: 0.072594822 | P28: 1000 | Q28: =G28*M28*0.000000001 -> 0.00013604932 | R28: =Q28*I28 -> 0.00013604932 | S28: =H28-1950 -> 65 | T28: =I28/N28 -> 10.276529 | U28: =N28*S28 -> 6.3250926 | V28: =IF(I28<U28,R28/(1-(1-I28/U28)^3),R28)*10000 -> 3.3736874 | W28: =I28/O28 -> 13.775087 | X28: =O28*S28 -> 4.7186635 | Y28: =IF(I28<X28,R28/(1-(1-I28/X28)^3),R28)*10000 -> 2.6647322 | Z28: =2021-1950 -> 71 | AA28: {=_xlfn.IFS(I28<=X28,R28*(3/(S28^3 - (S28-W28)^3)),I28>X28,R28*(3/S28^3))} -> 2.9109501e-09 | AB28: =(AA28/3)*(Z28^3)*10000 -> 3.4728702 | AC28: =Y28-AB28 -> -0.80813797 | AD28: =AB28*100/Y28 -> 130.32717
A29: Lor19_A_1 | B29: 53.5 | C29: 4.5 | D29: Fragments | E29: no | F29: -3.49 | G29: 9.59 | H29: 2014 | I29: 5 | J29: 87 | K29: 24790.195 | L29: 22.086957 | M29: 1.2247536 | N29: 0.13286297 | O29: 0.18146901 | P29: 39000 | Q29: =G29*M29*0.000000001 -> 1.1745387e-08 | R29: =Q29*I29 -> 5.8726936e-08 | S29: =H29-1950 -> 64 | T29: =I29/N29 -> 37.632758 | U29: =N29*S29 -> 8.50323 | V29: =IF(I29<U29,R29/(1-(1-I29/U29)^3),R29)*10000 -> 0.00063142389 | W29: =I29/O29 -> 27.552914 | X29: =O29*S29 -> 11.614017 | Y29: =IF(I29<X29,R29/(1-(1-I29/X29)^3),R29)*10000 -> 0.00072030386 | Z29: =2021-1950 -> 71 | AA29: {=_xlfn.IFS(I29<=X29,R29*(3/(S29^3 - (S29-W29)^3)),I29>X29,R29*(3/S29^3))} -> 8.2432235e-13 | AB29: =(AA29/3)*(Z29^3)*10000 -> 0.00098344679 | AC29: =Y29-AB29 -> -0.00026314293 | AD29: =AB29*100/Y29 -> 136.53221
A30: Jah19_A_1 | B30: -32.62011 | C30: 152.40008 | D30: Fragments | E30: 80% fragments | F30: -2.04 | G30: 64300 | H30: 2017 | I30: 5 | J30: 100 | K30: 0 | L30: 0 | M30: 1.0774797 | N30: 0.13341858 | O30: 0.015403806 | P30: 7000 | Q30: =G30*M30*0.000000001 -> 6.9281943e-05 | R30: =Q30*I30 -> 0.00034640971 | S30: =H30-1950 -> 67 | T30: =I30/N30 -> 37.476038 | U30: =N30*S30 -> 8.9390452 | V30: =IF(I30<U30,R30/(1-(1-I30/U30)^3),R30)*10000 -> 3.7882404 | W30: =I30/O30 -> 324.59511 | X30: =O30*S30 -> 1.032055 | Y30: =IF(I30<X30,R30/(1-(1-I30/X30)^3),R30)*10000 -> 3.4640971 | Z30: =2021-1950 -> 71 | AA30: {=_xlfn.IFS(I30<=X30,R30*(3/(S30^3 - (S30-W30)^3)),I30>X30,R30*(3/S30^3))} -> 3.4553091e-09 | AB30: =(AA30/3)*(Z30^3)*10000 -> 4.1223105 | AC30: =Y30-AB30 -> -0.65821335 | AD30: =AB30*100/Y30 -> 119.00101
A31: Lin17_A_1 | B31: -34.97 | C31: 150.79 | D31: Fibres | E31: 100% fibers | F31: -1.43 | G31: 78.8 | H31: 2015 | I31: 7 | J31: 55 | K31: 200.16216 | L31: 6.421875 | M31: 1.0774797 | N31: 0.13271872 | O31: 0.015681874 | P31: land | Q31: =G31*M31*0.000000001 -> 8.4905398e-08 | R31: =Q31*I31 -> 5.9433779e-07 | S31: =H31-1950 -> 65 | T31: =I31/N31 -> 52.743124 | U31: =N31*S31 -> 8.626717 | V31: =IF(I31<U31,R31/(1-(1-I31/U31)^3),R31)*10000 -> 0.0059834973 | W31: =I31/O31 -> 446.37521 | X31: =O31*S31 -> 1.0193218 | Y31: =IF(I31<X31,R31/(1-(1-I31/X31)^3),R31)*10000 -> 0.0059433779 | Z31: =2021-1950 -> 71 | AA31: {=_xlfn.IFS(I31<=X31,R31*(3/(S31^3 - (S31-W31)^3)),I31>X31,R31*(3/S31^3))} -> 6.4925384e-12 | AB31: =(AA31/3)*(Z31^3)*10000 -> 0.0077458364 | AC31: =Y31-AB31 -> -0.0018024585 | AD31: =AB31*100/Y31 -> 130.32717
A32: Lin17_A_2 | B32: -34.97 | C32: 150.79 | D32: Fragments | E32: 100% fragments | F32: -1.88 | G32: 36700 | H32: 2015 | I32: 7 | J32: 55 | K32: 200.16216 | L32: 6.421875 | M32: 1.0774797 | N32: 0.13271872 | O32: 0.015681874 | P32: land | Q32: =G32*M32*0.000000001 -> 3.9543504e-05 | R32: =Q32*I32 -> 0.00027680453 | S32: =H32-1950 -> 65 | T32: =I32/N32 -> 52.743124 | U32: =N32*S32 -> 8.626717 | V32: =IF(I32<U32,R32/(1-(1-I32/U32)^3),R32)*10000 -> 2.7867303 | W32: =I32/O32 -> 446.37521 | X32: =O32*S32 -> 1.0193218 | Y32: =IF(I32<X32,R32/(1-(1-I32/X32)^3),R32)*10000 -> 2.7680453 | Z32: =2021-1950 -> 71 | AA32: {=_xlfn.IFS(I32<=X32,R32*(3/(S32^3 - (S32-W32)^3)),I32>X32,R32*(3/S32^3))} -> 3.0238091e-09 | AB32: =(AA32/3)*(Z32^3)*10000 -> 3.6075152 | AC32: =Y32-AB32 -> -0.83946989 | AD32: =AB32*100/Y32 -> 130.32717
A33: Lin17_A_3 | B33: -35.24 | C33: 138.41 | D33: Fibres | E33: 100% fibers | F33: -1.82 | G33: 129 | H33: 2015 | I33: 7 | J33: 55 | K33: 2402.5207 | L33: 6.7957143 | M33: 0.82293429 | N33: 0.13257547 | O33: 0.023202468 | P33: 4000 | Q33: =G33*M33*0.000000001 -> 1.0615852e-07 | R33: =Q33*I33 -> 7.4310967e-07 | S33: =H33-1950 -> 65 | T33: =I33/N33 -> 52.800116 | U33: =N33*S33 -> 8.6174053 | V33: =IF(I33<U33,R33/(1-(1-I33/U33)^3),R33)*10000 -> 0.0074805574 | W33: =I33/O33 -> 301.69204 | X33: =O33*S33 -> 1.5081604 | Y33: =IF(I33<X33,R33/(1-(1-I33/X33)^3),R33)*10000 -> 0.0074310967 | Z33: =2021-1950 -> 71 | AA33: {=_xlfn.IFS(I33<=X33,R33*(3/(S33^3 - (S33-W33)^3)),I33>X33,R33*(3/S33^3))} -> 8.1177205e-12 | AB33: =(AA33/3)*(Z33^3)*10000 -> 0.0096847382 | AC33: =Y33-AB33 -> -0.0022536416 | AD33: =AB33*100/Y33 -> 130.32717
A34: Lin17_A_4 | B34: -35.24 | C34: 138.41 | D34: Fragments | E34: 100% fragments | F34: -1.85 | G34: 214000 | H34: 2015 | I34: 7 | J34: 55 | K34: 2402.5207 | L34: 6.7957143 | M34: 0.82293429 | N34: 0.13257547 | O34: 0.023202468 | P34: 4000 | Q34: =G34*M34*0.000000001 -> 0.00017610794 | R34: =Q34*I34 -> 0.0012327556 | S34: =H34-1950 -> 65 | T34: =I34/N34 -> 52.800116 | U34: =N34*S34 -> 8.6174053 | V34: =IF(I34<U34,R34/(1-(1-I34/U34)^3),R34)*10000 -> 12.409607 | W34: =I34/O34 -> 301.69204 | X34: =O34*S34 -> 1.5081604 | Y34: =IF(I34<X34,R34/(1-(1-I34/X34)^3),R34)*10000 -> 12.327556 | Z34: =2021-1950 -> 71 | AA34: {=_xlfn.IFS(I34<=X34,R34*(3/(S34^3 - (S34-W34)^3)),I34>X34,R34*(3/S34^3))} -> 1.3466606e-08 | AB34: =(AA34/3)*(Z34^3)*10000 -> 16.066155 | AC34: =Y34-AB34 -> -3.7385992 | AD34: =AB34*100/Y34 -> 130.32717
A35: Lin17_A_5 | B35: -42.74 | C35: 147.61 | D35: Fibres | E35: 100% fibers | F35: -1.64 | G35: 106 | H35: 2015 | I35: 7 | J35: 55 | K35: 352.81772 | L35: 6.2692308 | M35: 1.0774797 | N35: 0.1326194 | O35: 0.10082447 | P35: land | Q35: =G35*M35*0.000000001 -> 1.1421284e-07 | R35: =Q35*I35 -> 7.9948991e-07 | S35: =H35-1950 -> 65 | T35: =I35/N35 -> 52.782626 | U35: =N35*S35 -> 8.6202607 | V35: =IF(I35<U35,R35/(1-(1-I35/U35)^3),R35)*10000 -> 0.0080483433 | W35: =I35/O35 -> 69.427587 | X35: =O35*S35 -> 6.5535908 | Y35: =IF(I35<X35,R35/(1-(1-I35/X35)^3),R35)*10000 -> 0.0079948991 | Z35: =2021-1950 -> 71 | AA35: {=_xlfn.IFS(I35<=X35,R35*(3/(S35^3 - (S35-W35)^3)),I35>X35,R35*(3/S35^3))} -> 8.7336176e-12 | AB35: =(AA35/3)*(Z35^3)*10000 -> 0.010419526 | AC35: =Y35-AB35 -> -0.0024246269 | AD35: =AB35*100/Y35 -> 130.32717
A36: Lin17_A_6 | B36: -42.74 | C36: 147.61 | D36: Fragments | E36: 100% fragments | F36: -2.01 | G36: 61200 | H36: 2015 | I36: 7 | J36: 55 | K36: 352.81772 | L36: 6.2692308 | M36: 1.0774797 | N36: 0.1326194 | O36: 0.10082447 | P36: land | Q36: =G36*M36*0.000000001 -> 6.5941756e-05 | R36: =Q36*I36 -> 0.00046159229 | S36: =H36-1950 -> 65 | T36: =I36/N36 -> 52.782626 | U36: =N36*S36 -> 8.6202607 | V36: =IF(I36<U36,R36/(1-(1-I36/U36)^3),R36)*10000 -> 4.6467793 | W36: =I36/O36 -> 69.427587 | X36: =O36*S36 -> 6.5535908 | Y36: =IF(I36<X36,R36/(1-(1-I36/X36)^3),R36)*10000 -> 4.6159229 | Z36: =2021-1950 -> 71 | AA36: {=_xlfn.IFS(I36<=X36,R36*(3/(S36^3 - (S36-W36)^3)),I36>X36,R36*(3/S36^3))} -> 5.0424283e-09 | AB36: =(AA36/3)*(Z36^3)*10000 -> 6.0158018 | AC36: =Y36-AB36 -> -1.3998789 | AD36: =AB36*100/Y36 -> 130.32717
A37: Lin17_A_7 | B37: -38.08 | C37: 144.8 | D37: Fibres | E37: 100% fibers | F37: -1.65 | G37: 99.5 | H37: 2015 | I37: 7 | J37: 55 | K37: 1818.5587 | L37: 7.145 | M37: 1.0774797 | N37: 0.13246755 | O37: 0.32499763 | P37: 10000 | Q37: =G37*M37*0.000000001 -> 1.0720923e-07 | R37: =Q37*I37 -> 7.5046459e-07 | S37: =H37-1950 -> 65 | T37: =I37/N37 -> 52.843129 | U37: =N37*S37 -> 8.610391 | V37: =IF(I37<U37,R37/(1-(1-I37/U37)^3),R37)*10000 -> 0.0075540663 | W37: =I37/O37 -> 21.538619 | X37: =O37*S37 -> 21.124846 | Y37: =IF(I37<X37,R37/(1-(1-I37/X37)^3),R37)*10000 -> 0.010704571 | Z37: =2021-1950 -> 71 | AA37: {=_xlfn.IFS(I37<=X37,R37*(3/(S37^3 - (S37-W37)^3)),I37>X37,R37*(3/S37^3))} -> 1.1693659e-11 | AB37: =(AA37/3)*(Z37^3)*10000 -> 0.013950964 | AC37: =Y37-AB37 -> -0.0032463937 | AD37: =AB37*100/Y37 -> 130.32717
A38: Lin17_A_8 | B38: -38.08 | C38: 144.8 | D38: Fragments | E38: 100% fragments | F38: -1.74 | G38: 100000 | H38: 2015 | I38: 7 | J38: 55 | K38: 1818.5587 | L38: 7.145 | M38: 1.0774797 | N38: 0.13246755 | O38: 0.32499763 | P38: 10000 | Q38: =G38*M38*0.000000001 -> 0.00010774797 | R38: =Q38*I38 -> 0.00075423577 | S38: =H38-1950 -> 65 | T38: =I38/N38 -> 52.843129 | U38: =N38*S38 -> 8.610391 | V38: =IF(I38<U38,R38/(1-(1-I38/U38)^3),R38)*10000 -> 7.5920264 | W38: =I38/O38 -> 21.538619 | X38: =O38*S38 -> 21.124846 | Y38: =IF(I38<X38,R38/(1-(1-I38/X38)^3),R38)*10000 -> 10.758362 | Z38: =2021-1950 -> 71 | AA38: {=_xlfn.IFS(I38<=X38,R38*(3/(S38^3 - (S38-W38)^3)),I38>X38,R38*(3/S38^3))} -> 1.1752421e-08 | AB38: =(AA38/3)*(Z38^3)*10000 -> 14.02107 | AC38: =Y38-AB38 -> -3.2627072 | AD38: =AB38*100/Y38 -> 130.32717
A39: Nor14_A_1 | B39: 1.266762 | C39: 103.8005 | D39: Fibers | E39: 72% fibers | F39: -1.29 | G39: 0.577 | H39: 2012 | I39: 4 | J39: 16 | K39: 55.177509 | L39: 0 | M39: 1.6356767 | N39: 0.5527 | O39: 1.2212831 | P39: land | Q39: =G39*M39*0.000000001 -> 9.4378545e-10 | R39: =Q39*I39 -> 3.7751418e-09 | S39: =H39-1950 -> 62 | T39: =I39/N39 -> 7.2371992 | U39: =N39*S39 -> 34.2674 | V39: =IF(I39<U39,R39/(1-(1-I39/U39)^3),R39)*10000 -> 0.00012142601 | W39: =I39/O39 -> 3.275244 | X39: =O39*S39 -> 75.71955 | Y39: =IF(I39<X39,R39/(1-(1-I39/X39)^3),R39)*10000 -> 0.00025124892 | Z39: =2021-1950 -> 71 | AA39: {=_xlfn.IFS(I39<=X39,R39*(3/(S39^3 - (S39-W39)^3)),I39>X39,R39*(3/S39^3))} -> 3.1626446e-13 | AB39: =(AA39/3)*(Z39^3)*10000 -> 0.0003773151 | AC39: =Y39-AB39 -> -0.00012606618 | AD39: =AB39*100/Y39 -> 150.17581
A40: Wanb19_A_1 | B40: 37.11556 | C40: 122.48 | D40: Fibers | E40: 0.96 | F40: -1.69 | G40: 118 | H40: 2017 | I40: 5 | J40: 102 | M40: 0.61037441 | N40: 0.1324198 | O40: 0.49764695 | P40: 2000 | Q40: =G40*M40*0.000000001 -> 7.202418e-08 | R40: =Q40*I40 -> 3.601209e-07 | S40: =H40-1950 -> 67 | T40: =I40/N40 -> 37.758704 | U40: =N40*S40 -> 8.8721266 | V40: =IF(I40<U40,R40/(1-(1-I40/U40)^3),R40)*10000 -> 0.0039277267 | W40: =I40/O40 -> 10.047283 | X40: =O40*S40 -> 33.342346 | Y40: =IF(I40<X40,R40/(1-(1-I40/X40)^3),R40)*10000 -> 0.0093347053 | Z40: =2021-1950 -> 71 | AA40: {=_xlfn.IFS(I40<=X40,R40*(3/(S40^3 - (S40-W40)^3)),I40>X40,R40*(3/S40^3))} -> 9.3110242e-12 | AB40: =(AA40/3)*(Z40^3)*10000 -> 0.011108393 | AC40: =Y40-AB40 -> -0.001773688 | AD40: =AB40*100/Y40 -> 119.00101
A41: Wanb19_A_2 | B41: 37.11556 | C41: 122.50917 | D41: Fibers | E41: 0.95 | F41: -1.69 | G41: 77.6 | H41: 2017 | I41: 5 | J41: 102 | M41: 0.61037441 | N41: 0.1324198 | O41: 0.47844016 | P41: 3000 | Q41: =G41*M41*0.000000001 -> 4.7365054e-08 | R41: =Q41*I41 -> 2.3682527e-07 | S41: =H41-1950 -> 67 | T41: =I41/N41 -> 37.758704 | U41: =N41*S41 -> 8.8721266 | V41: =IF(I41<U41,R41/(1-(1-I41/U41)^3),R41)*10000 -> 0.0025829796 | W41: =I41/O41 -> 10.450628 | X41: =O41*S41 -> 32.055491 | Y41: =IF(I41<X41,R41/(1-(1-I41/X41)^3),R41)*10000 -> 0.0059392715 | Z41: =2021-1950 -> 71 | AA41: {=_xlfn.IFS(I41<=X41,R41*(3/(S41^3 - (S41-W41)^3)),I41>X41,R41*(3/S41^3))} -> 5.9242043e-12 | AB41: =(AA41/3)*(Z41^3)*10000 -> 0.007067793 | AC41: =Y41-AB41 -> -0.0011285214 | AD41: =AB41*100/Y41 -> 119.00101
...

Sheet One study one line 
A1: Name | B1: Lat | C1: Lon | D1: Shape | E1: Info shape | F1: Slope | G1: MP mass observation extrapolated to 1-5000 µm (µg/kg) from MPsizeBase | H1: year of sampling | I1: thickness of the sampled sediment layer (cm) | J1: reference numbrer in Martin dataset | K1: Distance_land (m) Martin dataset | L1: Water_Depth (m) Martin dataset | M1: Dry bulk density of the sediments (g/cm³) Martin dataset | N1: accumulation rate (cm/yr) Martin dataset | O1: Accumulation rate from Restreppo | P1: Distance to land NASA Ocean Biology Processing Group (m) | Q1: mass converted to g/cm³ | R1: mass converted to g/cm² | S1: accumulation time (yr) since 1950 | T1: time represented by the sampled sediment layer (yr) | U1: total thickness of the sediments (cm) since 1950 | V1: MP stock (g/m2) in year of study | W1: time represented by the sampled sediment layer (yr) | X1: total thickness of the sediments (cm) since 1950 | Y1: MP stock (g/m2) in year of study
A2: Alvarez-Ramirez2021 | B2: 31.82 | C2: -116.72 | D2: Fragments | E2: 100% fragments | F2: -3.83 | G2: 495 | H2: 2016 | I2: 5 | J2: 74 | K2: 4912.5226 | L2: 72.416667 | M2: 0.49520066 | N2: 0.13261896 | O2: 0.18873249 | P2: 5000 | Q2: =G2*M2*0.000000001 -> 2.4512433e-07 | R2: =Q2*I2 -> 1.2256216e-06 | S2: =H2-1950 -> 66 | T2: =I2/N2 -> 37.702 | U2: =N2*S2 -> 8.7528512 | V2: =IF(I2<U2,R2/(1-(1-I2/U2)^3),R2)*10000 -> 0.013304907 | W2: =I2/O2 -> 26.492524 | X2: =O2*S2 -> 12.456344 | Y2: =IF(I2<X2,R2/(1-(1-I2/X2)^3),R2)*10000 -> 0.015602868
A3: Huang2020 | B3: 18.415724 | C3: 110.05434 | D3: Fragments | E3: 61% fragments | F3: -1.59 | G3: 2060 | H3: 2018 | I3: 5 | J3: 76 | K3: 257.49504 | L3: 5.5 | M3: 1.6589305 | N3: 0.2027 | O3: 0.25807987 | P3: 1000 | Q3: =G3*M3*0.000000001 -> 3.4173968e-06 | R3: =Q3*I3 -> 1.7086984e-05 | S3: =H3-1950 -> 68 | T3: =I3/N3 -> 24.666996 | U3: =N3*S3 -> 13.7836 | V3: =IF(I3<U3,R3/(1-(1-I3/U3)^3),R3)*10000 -> 0.23052494 | W3: =I3/O3 -> 19.373847 | X3: =O3*S3 -> 17.549431 | Y3: =IF(I3<X3,R3/(1-(1-I3/X3)^3),R3)*10000 -> 0.26936831
A4: Haave2019 | B4: =AVERAGE('MPsizeBase+parameters'!B26:B28) -> 60.437415 | C4: =AVERAGE('MPsizeBase+parameters'!C26:C28) -> 5.2377308 | D4: Fragments | E4: none | F4: =AVERAGE('MPsizeBase+parameters'!F26:F28) -> -2.8633333 | G4: =AVERAGE('MPsizeBase+parameters'!G26:G28) -> 204466.67 | H4: =AVERAGE('MPsizeBase+parameters'!H26:H28) -> 2015 | I4: =AVERAGE('MPsizeBase+parameters'!I26:I28) -> 1 | J4: =AVERAGE('MPsizeBase+parameters'!J26:J28) -> 72 | K4: =AVERAGE('MPsizeBase+parameters'!K26:K28) -> 115872.77 | L4: =AVERAGE('MPsizeBase+parameters'!L26:L28) -> 323.33333 | M4: =AVERAGE('MPsizeBase+parameters'!M26:M28) -> 3.4884441 | ... Y4: =AVERAGE('MPsizeBase+parameters'!Y26:Y28) -> 13.970485
A5: Lorentz2019 | B5: 53.5 | C5: 4.5 | D5: Fragments | E5: none | F5: -3.49 | G5: 9.59 | H5: 2014 | I5: 5 | J5: 87 | K5: 24790.195 | L5: 22.086957 | M5: 1.2247536 | N5: 0.13286297 | O5: 0.18146901 | P5: 39000 | Q5: =G5*M5*0.000000001 -> 1.1745387e-08 | R5: =Q5*I5 -> 5.8726936e-08 | S5: =H5-1950 -> 64 | T5: =I5/N5 -> 37.632758 | U5: =N5*S5 -> 8.50323 | V5: =IF(I5<U5,R5/(1-(1-I5/U5)^3),R5)*10000 -> 0.00063142389 | W5: =I5/O5 -> 27.552914 | X5: =O5*S5 -> 11.614017 | Y5: =IF(I5<X5,R5/(1-(1-I5/X5)^3),R5)*10000 -> 0.00072030386
A6: Jahan2019 | B6: -32.62011 | C6: 152.40008 | D6: Fragments | E6: 80% fragments | F6: -2.04 | G6: 64300 | H6: 2017 | I6: 5 | J6: 100 | K6: 0 | L6: 0 | M6: 1.0774797 | N6: 0.13341858 | O6: 0.015403806 | P6: 7000 | Q6: =G6*M6*0.000000001 -> 6.9281943e-05 | R6: =Q6*I6 -> 0.00034640971 | S6: =H6-1950 -> 67 | T6: =I6/N6 -> 37.476038 | U6: =N6*S6 -> 8.9390452 | V6: =IF(I6<U6,R6/(1-(1-I6/U6)^3),R6)*10000 -> 3.7882404 | W6: =I6/O6 -> 324.59511 | X6: =O6*S6 -> 1.032055 | Y6: =IF(I6<X6,R6/(1-(1-I6/X6)^3),R6)*10000 -> 3.4640971
A7: Ling2019 | B7: =AVERAGE('MPsizeBase+parameters'!B32,'MPsizeBase+parameters'!B34,'MPsizeBase+parameters'!B36,'MPsizeBase+parameters'!B38) -> -37.7575 | C7: =AVERAGE('MPsizeBase+parameters'!C32,'MPsizeBase+parameters'!C34,'MPsizeBase+parameters'!C36,'MPsizeBase+parameters'!C38) -> 145.4025 | D7: Fragments | E7: 100% fragments | F7: =AVERAGE('MPsizeBase+parameters'!F32,'MPsizeBase+parameters'!F34,'MPsizeBase+parameters'!F36,'MPsizeBase+parameters'!F38) -> -1.87 | G7: =AVERAGE('MPsizeBase+parameters'!G32,'MPsizeBase+parameters'!G34,'MPsizeBase+parameters'!G36,'MPsizeBase+parameters'!G38) -> 102975 | H7: =AVERAGE('MPsizeBase+parameters'!H32,'MPsizeBase+parameters'!H34,'MPsizeBase+parameters'!H36,'MPsizeBase+parameters'!H38) -> 2015 | I7: =AVERAGE('MPsizeBase+parameters'!I32,'MPsizeBase+parameters'!I34,'MPsizeBase+parameters'!I36,'MPsizeBase+parameters'!I38) -> 7 | J7: =AVERAGE('MPsizeBase+parameters'!J32,'MPsizeBase+parameters'!J34,'MPsizeBase+parameters'!J36,'MPsizeBase+parameters'!J38) -> 55 | K7: =AVERAGE('MPsizeBase+parameters'!K32,'MPsizeBase+parameters'!K34,'MPsizeBase+parameters'!K36,'MPsizeBase+parameters'!K38) -> 1193.5148 | L7: =AVERAGE('MPsizeBase+parameters'!L32,'MPsizeBase+parameters'!L34,'MPsizeBase+parameters'!L36,'MPsizeBase+parameters'!L38) -> 6.657955 | M7: =AVERAGE('MPsizeBase+parameters'!M32,'MPsizeBase+parameters'!M34,'MPsizeBase+parameters'!M36,'MPsizeBase+parameters'!M38) -> 1.0138433 | ... Y7: =AVERAGE('MPsizeBase+parameters'!Y32,'MPsizeBase+parameters'!Y34,'MPsizeBase+parameters'!Y36,'MPsizeBase+parameters'!Y38) -> 7.6174716
A8: Bikir2023 | B8: =AVERAGE('MPsizeBase+parameters'!B64:B77) -> 52.919737 | C8: =AVERAGE('MPsizeBase+parameters'!C64:C77) -> -0.90217014 | D8: Fragments | E8: 73% fragments | F8: =AVERAGE('MPsizeBase+parameters'!F64:F77) -> -1.36 | G8: =AVERAGE('MPsizeBase+parameters'!G64:G77) -> 1316500 | H8: =AVERAGE('MPsizeBase+parameters'!H64:H77) -> 2017 | I8: =AVERAGE('MPsizeBase+parameters'!I64:I77) -> 3.1032092 | J8: Nela | K8: =AVERAGE('MPsizeBase+parameters'!K64:K77) -> 44714.286 | M8: =AVERAGE('MPsizeBase+parameters'!M64:M77) -> 1.2342588 | O8: =AVERAGE('MPsizeBase+parameters'!O64:O77) -> 0.08426364 | P8: =AVERAGE('MPsizeBase+parameters'!P64:P77) -> 44714.286 | Q8: =AVERAGE('MPsizeBase+parameters'!Q64:Q77) -> 0.0017688158 | R8: =AVERAGE('MPsizeBase+parameters'!R64:R77) -> 0.0055421798 | S8: =AVERAGE('MPsizeBase+parameters'!S64:S77) -> 67 | W8: =AVERAGE('MPsizeBase+parameters'!W64:W77) -> 37.302454 | X8: =AVERAGE('MPsizeBase+parameters'!X64:X77) -> 5.6456639 | Y8: =AVERAGE('MPsizeBase+parameters'!Y64:Y77) -> 60.863783
A9: Kim2023 | B9: =AVERAGE('MPsizeBase+parameters'!B78:B83) -> 74.310627 | C9: =AVERAGE('MPsizeBase+parameters'!C78:C83) -> -172.94976 | D9: Fragments | E9: =AVERAGE('MPsizeBase+parameters'!E78:E83) -> 0.99333333 | F9: =AVERAGE('MPsizeBase+parameters'!F78:F83) -> -1.84 | G9: =AVERAGE('MPsizeBase+parameters'!G78:G83) -> 45400 | H9: =AVERAGE('MPsizeBase+parameters'!H78:H83) -> 2017 | I9: =AVERAGE('MPsizeBase+parameters'!I78:I83) -> 2 | J9: Nela | K9: =AVERAGE('MPsizeBase+parameters'!K78:K83) -> 305000 | L9: =AVERAGE('MPsizeBase+parameters'!L78:L83) -> 236.83333 | M9: =AVERAGE('MPsizeBase+parameters'!M78:M83) -> 0.48083333 | O9: =AVERAGE('MPsizeBase+parameters'!O78:O83) -> 0.049568059 | P9: =AVERAGE('MPsizeBase+parameters'!P78:P83) -> 391166.67 | Q9: =AVERAGE('MPsizeBase+parameters'!Q78:Q83) -> 2.1662667e-05 | R9: =AVERAGE('MPsizeBase+parameters'!R78:R83) -> 4.3325333e-05 | S9: =AVERAGE('MPsizeBase+parameters'!S78:S83) -> 67 | W9: =AVERAGE('MPsizeBase+parameters'!W78:W83) -> 105.60384 | X9: =AVERAGE('MPsizeBase+parameters'!X78:X83) -> 3.32106 | Y9: =AVERAGE('MPsizeBase+parameters'!Y78:Y83) -> 0.57242274
A10: Wang2019a | B10: =AVERAGE('MPsizeBase+parameters'!B3:B16) -> 34.592857 | C10: =AVERAGE('MPsizeBase+parameters'!C3:C16) -> 122.55714 | D10: Fibers | E10: =AVERAGE('MPsizeBase+parameters'!E3:E16) -> 0.83997143 | F10: =AVERAGE('MPsizeBase+parameters'!F3:F16) -> -1.5464286 | G10: =AVERAGE('MPsizeBase+parameters'!G3:G16) -> 93.128571 | H10: =AVERAGE('MPsizeBase+parameters'!H3:H16) -> 2017 | I10: =AVERAGE('MPsizeBase+parameters'!I3:I16) -> 3 | J10: =AVERAGE('MPsizeBase+parameters'!J3:J16) -> 1 | K10: =AVERAGE('MPsizeBase+parameters'!K3:K16) -> 140.24283 | L10: =AVERAGE('MPsizeBase+parameters'!L3:L16) -> 43.285714 | ... Y10: =AVERAGE('MPsizeBase+parameters'!Y3:Y16) -> 0.0044744069
A11: Mu2019 | B11: 66 | C11: -168 | D11: Fibers | E11: 64% fibers | F11: -1.22 | G11: 1.31 | H11: 2017 | I11: 5 | J11: 2 | K11: 155053.86 | L11: 71.16 | M11: 0.81517199 | N11: 0.12429491 | O11: 0.063551595 | P11: 27000 | Q11: =G11*M11*0.000000001 -> 1.0678753e-09 | R11: =Q11*I11 -> 5.3393765e-09 | S11: =H11-1950 -> 67 | T11: =I11/N11 -> 40.22691 | U11: =N11*S11 -> 8.3277587 | V11: =IF(I11<U11,R11/(1-(1-I11/U11)^3),R11)*10000 -> 5.7032886e-05 | W11: =I11/O11 -> 78.676232 | X11: =O11*S11 -> 4.2579569 | Y11: =IF(I11<X11,R11/(1-(1-I11/X11)^3),R11)*10000 -> 5.3393765e-05
A12: Alvarez-Ramirez2020 | B12: 31.82 | C12: -116.72 | D12: Fibers | E12: 100% fibers | F12: -2.16 | G12: 27.7 | H12: 2016 | I12: 5 | J12: 74 | K12: 4912.5226 | L12: 72.416667 | M12: 0.49520066 | N12: 0.13261896 | O12: 0.18873249 | P12: 5000 | Q12: =G12*M12*0.000000001 -> 1.3717058e-08 | R12: =Q12*I12 -> 6.8585291e-08 | S12: =H12-1950 -> 66 | T12: =I12/N12 -> 37.702 | U12: =N12*S12 -> 8.7528512 | V12: =IF(I12<U12,R12/(1-(1-I12/U12)^3),R12)*10000 -> 0.0007445372 | W12: =I12/O12 -> 26.492524 | X12: =O12*S12 -> 12.456344 | Y12: =IF(I12<X12,R12/(1-(1-I12/X12)^3),R12)*10000 -> 0.00087313016
A13: Zhang2020 | B13: 30.45 | C13: 122.45 | D13: Fibers | E13: 92% fibers | F13: -1.27 | G13: 3.56 | H13: 2018 | I13: 5 | J13: 75 | K13: 50416.724 | L13: 21.65 | M13: 0.61037441 | N13: 0.1310078 | O13: 1.0224486 | P13: 1000 | Q13: =G13*M13*0.000000001 -> 2.1729329e-09 | R13: =Q13*I13 -> 1.0864664e-08 | S13: =H13-1950 -> 68 | T13: =I13/N13 -> 38.165667 | U13: =N13*S13 -> 8.9085302 | V13: =IF(I13<U13,R13/(1-(1-I13/U13)^3),R13)*10000 -> 0.00011866874 | W13: =I13/O13 -> 4.8902215 | X13: =O13*S13 -> 69.526503 | Y13: =IF(I13<X13,R13/(1-(1-I13/X13)^3),R13)*10000 -> 0.00054160386
A14: Huang2020 | B14: =AVERAGE('MPsizeBase+parameters'!B21:B23) -> 18.410284 | C14: =AVERAGE('MPsizeBase+parameters'!C21:C23) -> 110.00823 | D14: Fibers | E14: 65% fibers | F14: =AVERAGE('MPsizeBase+parameters'!F21:F23) -> -1.71 | G14: =AVERAGE('MPsizeBase+parameters'!G21:G23) -> 36.673333 | H14: =AVERAGE('MPsizeBase+parameters'!H21:H23) -> 2018 | I14: =AVERAGE('MPsizeBase+parameters'!I21:I23) -> 5 | J14: =AVERAGE('MPsizeBase+parameters'!J21:J23) -> 76 | K14: =AVERAGE('MPsizeBase+parameters'!K21:K23) -> 182.39232 | L14: =AVERAGE('MPsizeBase+parameters'!L21:L23) -> 4.6333333 | M14: =AVERAGE('MPsizeBase+parameters'!M21:M23) -> 1.4754725 | ... Y14: =AVERAGE('MPsizeBase+parameters'!Y21:Y23) -> 0.0044744167
A15: Alv19_A_1 | B15: -22.84 | C15: -43.16 | D15: Fibers | E15: 81% fibers | F15: -2.67 | G15: 6470 | H15: 2017 | I15: 5 | J15: 84 | K15: 2321.4787 | L15: 0 | M15: 1.3738833 | N15: 0.13341858 | O15: 0.89874914 | P15: 2000 | Q15: =G15*M15*0.000000001 -> 8.8890248e-06 | R15: =Q15*I15 -> 4.4445124e-05 | S15: =H15-1950 -> 67 | T15: =I15/N15 -> 37.476038 | U15: =N15*S15 -> 8.9390452 | V15: =IF(I15<U15,R15/(1-(1-I15/U15)^3),R15)*10000 -> 0.48603953 | W15: =I15/O15 -> 5.5632877 | X15: =O15*S15 -> 60.216192 | Y15: =IF(I15<X15,R15/(1-(1-I15/X15)^3),R15)*10000 -> 1.9409121
A16: Ling2019 | B16: =AVERAGE('MPsizeBase+parameters'!B31,'MPsizeBase+parameters'!B33,'MPsizeBase+parameters'!B35,'MPsizeBase+parameters'!B37) -> -37.7575 | C16: =AVERAGE('MPsizeBase+parameters'!C31,'MPsizeBase+parameters'!C33,'MPsizeBase+parameters'!C35,'MPsizeBase+parameters'!C37) -> 145.4025 | D16: Fibers | E16: 100% fibers | F16: =AVERAGE('MPsizeBase+parameters'!F31,'MPsizeBase+parameters'!F33,'MPsizeBase+parameters'!F35,'MPsizeBase+parameters'!F37) -> -1.635 | G16: =AVERAGE('MPsizeBase+parameters'!G31,'MPsizeBase+parameters'!G33,'MPsizeBase+parameters'!G35,'MPsizeBase+parameters'!G37) -> 103.325 | H16: =AVERAGE('MPsizeBase+parameters'!H31,'MPsizeBase+parameters'!H33,'MPsizeBase+parameters'!H35,'MPsizeBase+parameters'!H37) -> 2015 | I16: =AVERAGE('MPsizeBase+parameters'!I31,'MPsizeBase+parameters'!I33,'MPsizeBase+parameters'!I35,'MPsizeBase+parameters'!I37) -> 7 | J16: =AVERAGE('MPsizeBase+parameters'!J31,'MPsizeBase+parameters'!J33,'MPsizeBase+parameters'!J35,'MPsizeBase+parameters'!J37) -> 55 | K16: =AVERAGE('MPsizeBase+parameters'!K31,'MPsizeBase+parameters'!K33,'MPsizeBase+parameters'!K35,'MPsizeBase+parameters'!K37) -> 1193.5148 | L16: =AVERAGE('MPsizeBase+parameters'!L31,'MPsizeBase+parameters'!L33,'MPsizeBase+parameters'!L35,'MPsizeBase+parameters'!L37) -> 6.657955 | M16: =AVERAGE('MPsizeBase+parameters'!M31,'MPsizeBase+parameters'!M33,'MPsizeBase+parameters'!M35,'MPsizeBase+parameters'!M37) -> 1.0138433 | ... Y16: =AVERAGE('MPsizeBase+parameters'!Y31,'MPsizeBase+parameters'!Y33,'MPsizeBase+parameters'!Y35,'MPsizeBase+parameters'!Y37) -> 0.008018486
A17: Wang2019b | B17: =AVERAGE('MPsizeBase+parameters'!B40:B63) -> 37.083823 | C17: =AVERAGE('MPsizeBase+parameters'!C40:C63) -> 122.55336 | D17: Fibers | E17: =AVERAGE('MPsizeBase+parameters'!E40:E63) -> 0.88416667 | F17: =AVERAGE('MPsizeBase+parameters'!F40:F63) -> -1.65625 | G17: =AVERAGE('MPsizeBase+parameters'!G40:G63) -> 94.8 | H17: =AVERAGE('MPsizeBase+parameters'!H40:H63) -> 2017 | I17: =AVERAGE('MPsizeBase+parameters'!I40:I63) -> 5 | J17: =AVERAGE('MPsizeBase+parameters'!J40:J63) -> 102 | M17: =AVERAGE('MPsizeBase+parameters'!M40:M63) -> 0.61037441 | N17: =AVERAGE('MPsizeBase+parameters'!N40:N63) -> 0.1324198 | O17: =AVERAGE('MPsizeBase+parameters'!O40:O63) -> 0.45743137 | P17: =AVERAGE('MPsizeBase+parameters'!P40:P63) -> 3833.3333 | Q17: =AVERAGE('MPsizeBase+parameters'!Q40:Q63) -> 5.7863494e-08 | R17: =AVERAGE('MPsizeBase+parameters'!R40:R63) -> 2.8931747e-07 | S17: =AVERAGE('MPsizeBase+parameters'!S40:S63) -> 67 | T17: =AVERAGE('MPsizeBase+parameters'!T40:T63) -> 37.758704 | ... Y17: =AVERAGE('MPsizeBase+parameters'!Y40:Y63) -> 0.0071202383
A18: Chen2018 | B18: 29.51 | C18: 121.504 | D18: Fibers | E18: 63% fibers | F18: -2.04 | G18: 702 | H18: 2017 | I18: 5 | J18: 6 | K18: 1738 | M18: 0.61037441 | N18: 0.13341858 | O18: 0.587512 | P18: 1000 | Q18: =G18*M18*0.000000001 -> 4.2848284e-07 | R18: =Q18*I18 -> 2.1424142e-06 | S18: =H18-1950 -> 67 | T18: =I18/N18 -> 37.476038 | U18: =N18*S18 -> 8.9390452 | V18: =IF(I18<U18,R18/(1-(1-I18/U18)^3),R18)*10000 -> 0.023428846 | W18: =I18/O18 -> 8.5104644 | X18: =O18*S18 -> 39.363304 | Y18: =IF(I18<X18,R18/(1-(1-I18/X18)^3),R18)*10000 -> 0.064007813
C21: mean slope fibers : | F21: =AVERAGE(F10:F18) -> -1.7675198 | U21: geomean stock fibers g/m2 : | Y21: =GEOMEAN(Y10:Y18) -> 0.0053491308 | Z21: g/m2
C22: mean slope fragments : | F22: =AVERAGE(F2:F9) -> -2.3604167 | U22: geomean stock fragments g/m2 : | Y22: =GEOMEAN(Y2:Y9) -> 0.66637602 | Z22: g/m2
C23: mean slope fragments confident: | F23: =AVERAGE(F2,F3,F6,F7,F8,F9) -> -2.0883333 | U23: geomean stock confident fragments g/m2 : | Y23: =GEOMEAN(Y2,Y3,Y6,Y7,Y8,Y9) -> 1.2526736 | Z23: g/m2
U25: First estimation
U26: Surface (from Sonke 22) | Y26: 35300000000000 | Z26: m2
U27: Total stock of marine sediments fibers : | Y27: =Y26*Y21*0.000000000001 -> 0.18882432 | Z27: Tg
U28: Total stock of confident marine sediments fragments : | Y28: =Y26*Y22*0.000000000001 -> 23.523073 | Z28: Tg
U29: Total stock of marine sediments fragments : | Y29: =Y26*Y23*0.000000000001 -> 44.21938 | Z29: Tg

Sheet Mean slope extrapolates
A1: Author | B1: link | C1: Lat | D1: Lon | E1: Shape | F1: Info shape | G1: Slope | H1: Smallest | I1: Concentration reported MP/kgdw | J1: Intercept | K1: Intercept new | L1: Mass extrapolated µg/kg | M1: year of sampling | N1: thickness of the sampled sediment layer (cm) | O1: reference numbrer in Martin dataset | P1: Distance_land (m) Martin dataset | Q1: Water_Depth (m) Martin dataset | R1: Dry bulk density of the sediments (g/cm³) Martin dataset | S1: accumulation rate (cm/yr) Martin dataset | T1: Accumulation rate from Restreppo | U1: Distance to land NASA Ocean Biology Processing Group (m) | V1: mass converted to g/cm³ | W1: mass converted to g/cm² | X1: accumulation time (yr) since 1950 | Y1: time represented by the sampled sediment layer (yr) | Z1: total thickness of the sediments (cm) since 1950 | AA1: MP stock (g/m2) in year of study | AB1: time represented by the sampled sediment layer (yr) | AC1: total thickness of the sediments (cm) since 1950 | AD1: MP stock (g/m2) in year of study | AE1: accumulation time (yr) since 1950 | AF1: parameter a | AG1: MP stock (g/m2) in 2021 | AH1: Difference | AI1: % Difference
A2: Detailed studies in MPsizeBase
A3: Wang et al., | B3: High levels of microplastic pollution in the sediments and benthic organisms of the South Yellow Sea, China - ScienceDirect | C3: 35.3 | D3: 122.19 | E3: Fibers | F3: 0.83997143 | G3: -1.5464286 | H3: 50 | I3: 2650 | J3: =LOG(I3, 10) - (G3) * LOG(H3,10)^(G3+1) -> 4.5808227 | K3: =-1*10^J3*(G3+1) -> 20814.025 | L3: =IF(E3="Fragments",0.000000097*K3*(5000^(4+G3)-1)/(4+G3),0.000106*K3*(5000^(2+G3)-1)/(2+G3)) -> 226.74898 | M3: 2017 | N3: 20 | O3: 1 | P3: 144.84096 | Q3: 39 | R3: 0.61037441 | S3: 0.29850746 | T3: 0.29850746 | U3: 136000 | V3: =L3*R3*0.000000001 -> 1.3840177e-07 | W3: =V3*N3 -> 2.7680354e-06 | X3: =M3-1950 -> 67 | Y3: =N3/S3 -> 67 | Z3: =S3*X3 -> 20 | AA3: =IF(N3<Z3,W3/(1-(1-N3/Z3)^3),W3)*10000 -> 0.027680354 | AB3: =N3/T3 -> 67 | AC3: =T3*X3 -> 20 | AD3: =IF(N3<AC3,W3/(1-(1-N3/AC3)^3),W3)*10000 -> 0.027680354 | AE3: =2021-1950 -> 71 | AF3: {=_xlfn.IFS(N3<=AC3,W3*(3/(X3^3 - (X3-AB3)^3)),N3>AC3,W3*(3/X3^3))} -> 2.7610133e-11 | AG3: =(AF3/3)*(AE3^3)*10000 -> 0.032939901 | AH3: =AD3-AG3 -> -0.0052595462 | AI3: =AG3*100/AD3 -> 119.00101
A4: HS3 | B4: High levels of microplastic pollution in the sediments and benthic organisms of the South Yellow Sea, China - ScienceDirect | C4: 35 | D4: 121.19 | E4: Fibers | F4: 0.83997143 | G4: -1.5464286 | H4: 50 | I4: 2891.2278 | J4: =LOG(I4, 10) - (G4) * LOG(H4,10)^(G4+1) -> 4.6186591 | K4: =-1*10^J4*(G4+1) -> 22708.713 | L4: =IF(E4="Fragments",0.000000097*K4*(5000^(4+G4)-1)/(4+G4),0.000106*K4*(5000^(2+G4)-1)/(2+G4)) -> 247.38979 | M4: 2017 | N4: 20 | O4: 1 | P4: 112.65408 | Q4: 66 | R4: 0.61037441 | S4: 0.29850746 | T4: 0.29850746 | U4: 103000 | V4: =L4*R4*0.000000001 -> 1.510004e-07 | W4: =V4*N4 -> 3.0200079e-06 | X4: =M4-1950 -> 67 | Y4: =N4/S4 -> 67 | Z4: =S4*X4 -> 20 | AA4: =IF(N4<Z4,W4/(1-(1-N4/Z4)^3),W4)*10000 -> 0.030200079 | AB4: =N4/T4 -> 67 | AC4: =T4*X4 -> 20 | AD4: =IF(N4<AC4,W4/(1-(1-N4/AC4)^3),W4)*10000 -> 0.030200079 | AE4: =2021-1950 -> 71 | AF4: {=_xlfn.IFS(N4<=AC4,W4*(3/(X4^3 - (X4-AB4)^3)),N4>AC4,W4*(3/X4^3))} -> 3.0123465e-11 | AG4: =(AF4/3)*(AE4^3)*10000 -> 0.035938399 | AH4: =AD4-AG4 -> -0.0057383193 | AI4: =AG4*100/AD4 -> 119.00101
A5: HS1 | B5: High levels of microplastic pollution in the sediments and benthic organisms of the South Yellow Sea, China - ScienceDirect | C5: 36 | D5: 124 | E5: Fibers | F5: 0.83997143 | G5: -1.5464286 | H5: 50 | I5: 4384.5048 | J5: =LOG(I5, 10) - (G5) * LOG(H5,10)^(G5+1) -> 4.7994974 | K5: =-1*10^J5*(G5+1) -> 34437.432 | L5: =IF(E5="Fragments",0.000000097*K5*(5000^(4+G5)-1)/(4+G5),0.000106*K5*(5000^(2+G5)-1)/(2+G5)) -> 375.16301 | M5: 2017 | N5: 20 | O5: 1 | P5: 160.9344 | Q5: 75 | R5: 0.61037441 | S5: 0.29850746 | T5: 0.29850746 | U5: 157000 | V5: =L5*R5*0.000000001 -> 2.289899e-07 | W5: =V5*N5 -> 4.579798e-06 | X5: =M5-1950 -> 67 | Y5: =N5/S5 -> 67 | Z5: =S5*X5 -> 20 | AA5: =IF(N5<Z5,W5/(1-(1-N5/Z5)^3),W5)*10000 -> 0.04579798 | AB5: =N5/T5 -> 67 | AC5: =T5*X5 -> 20 | AD5: =IF(N5<AC5,W5/(1-(1-N5/AC5)^3),W5)*10000 -> 0.04579798 | AE5: =2021-1950 -> 71 | AF5: {=_xlfn.IFS(N5<=AC5,W5*(3/(X5^3 - (X5-AB5)^3)),N5>AC5,W5*(3/X5^3))} -> 4.5681796e-11 | AG5: =(AF5/3)*(AE5^3)*10000 -> 0.054500057 | AH5: =AD5-AG5 -> -0.0087020776 | AI5: =AG5*100/AD5 -> 119.00101
A6: Zhang et al., | B6: Microplastic pollution in water, sediment, and fish from artificial reefs around the Ma’an Archipelago, Shengsi, China - ScienceDirect | C6: 30.803 | D6: 122.655 | E6: Fibers | F6: 92% fibers | G6: -1.27 | H6: 50 | I6: 69 | J6: =LOG(I6, 10) - (G6) * LOG(H6,10)^(G6+1) -> 2.9395101 | K6: =-1*10^J6*(G6+1) -> 234.89505 | L6: =IF(E6="Fragments",0.000000097*K6*(5000^(4+G6)-1)/(4+G6),0.000106*K6*(5000^(2+G6)-1)/(2+G6)) -> 17.070179 | M6: 2018 | N6: 5 | O6: 75 | P6: 60269.933 | Q6: 18.2 | R6: 0.61037441 | S6: 0.1310078 | T6: 0.65010635 | U6: 3000 | V6: =L6*R6*0.000000001 -> 1.04192e-08 | W6: =V6*N6 -> 5.2096001e-08 | X6: =M6-1950 -> 68 | Y6: =N6/S6 -> 38.165667 | Z6: =S6*X6 -> 8.9085302 | AA6: =IF(N6<Z6,W6/(1-(1-N6/Z6)^3),W6)*10000 -> 0.0005690159 | AB6: =N6/T6 -> 7.6910493 | AC6: =T6*X6 -> 44.207232 | AD6: =IF(N6<AC6,W6/(1-(1-N6/AC6)^3),W6)*10000 -> 0.0017228621 | AE6: =2021-1950 -> 71 | AF6: {=_xlfn.IFS(N6<=AC6,W6*(3/(X6^3 - (X6-AB6)^3)),N6>AC6,W6*(3/X6^3))} -> 1.6437851e-12 | AG6: =(AF6/3)*(AE6^3)*10000 -> 0.0019610959 | AH6: =AD6-AG6 -> -0.00023823378 | AI6: =AG6*100/AD6 -> 113.82779
A7: Zhang et al., | B7: Microplastic pollution in water, sediment, and fish from artificial reefs around the Ma’an Archipelago, Shengsi, China - ScienceDirect | C7: 30.732 | D7: 122.818 | E7: Fibers | F7: 92% fibers | G7: -1.27 | H7: 50 | I7: 64.4 | J7: =LOG(I7, 10) - (G7) * LOG(H7,10)^(G7+1) -> 2.9095469 | K7: =-1*10^J7*(G7+1) -> 219.23538 | L7: =IF(E7="Fragments",0.000000097*K7*(5000^(4+G7)-1)/(4+G7),0.000106*K7*(5000^(2+G7)-1)/(2+G7)) -> 15.932167 | M7: 2018 | N7: 5 | O7: 75 | P7: 77248.512 | Q7: 22.5 | R7: 0.61037441 | S7: 0.13044461 | T7: 0.68162843 | U7: land | V7: =L7*R7*0.000000001 -> 9.7245868e-09 | W7: =V7*N7 -> 4.8622934e-08 | X7: =M7-1950 -> 68 | Y7: =N7/S7 -> 38.330446 | Z7: =S7*X7 -> 8.8702333 | AA7: =IF(N7<Z7,W7/(1-(1-N7/Z7)^3),W7)*10000 -> 0.00053027548 | AB7: =N7/T7 -> 7.3353748 | AC7: =T7*X7 -> 46.350733 | AD7: =IF(N7<AC7,W7/(1-(1-N7/AC7)^3),W7)*10000 -> 0.0016768559 | AE7: =2021-1950 -> 71 | AF7: {=_xlfn.IFS(N7<=AC7,W7*(3/(X7^3 - (X7-AB7)^3)),N7>AC7,W7*(3/X7^3))} -> 1.5998905e-12 | AG7: =(AF7/3)*(AE7^3)*10000 -> 0.001908728 | AH7: =AD7-AG7 -> -0.00023187212 | AI7: =AG7*100/AD7 -> 113.82779
A8: Zhang et al., | B8: Microplastic pollution in water, sediment, and fish from artificial reefs around the Ma’an Archipelago, Shengsi, China - ScienceDirect | C8: 30.697 | D8: 122.796 | E8: Fibers | F8: 92% fibers | G8: -1.27 | H8: 50 | I8: 55.2 | J8: =LOG(I8, 10) - (G8) * LOG(H8,10)^(G8+1) -> 2.8426001 | K8: =-1*10^J8*(G8+1) -> 187.91604 | L8: =IF(E8="Fragments",0.000000097*K8*(5000^(4+G8)-1)/(4+G8),0.000106*K8*(5000^(2+G8)-1)/(2+G8)) -> 13.656143 | M8: 2018 | N8: 5 | O8: 75 | P8: 76347.279 | Q8: 23.8 | R8: 0.61037441 | S8: 0.13027482 | T8: 0.68162843 | U8: 1000 | V8: =L8*R8*0.000000001 -> 8.3353601e-09 | W8: =V8*N8 -> 4.1676801e-08 | X8: =M8-1950 -> 68 | Y8: =N8/S8 -> 38.380403 | Z8: =S8*X8 -> 8.8586876 | AA8: =IF(N8<Z8,W8/(1-(1-N8/Z8)^3),W8)*10000 -> 0.0004543143 | AB8: =N8/T8 -> 7.3353748 | AC8: =T8*X8 -> 46.350733 | AD8: =IF(N8<AC8,W8/(1-(1-N8/AC8)^3),W8)*10000 -> 0.001437305 | AE8: =2021-1950 -> 71 | AF8: {=_xlfn.IFS(N8<=AC8,W8*(3/(X8^3 - (X8-AB8)^3)),N8>AC8,W8*(3/X8^3))} -> 1.3713347e-12 | AG8: =(AF8/3)*(AE8^3)*10000 -> 0.0016360526 | AH8: =AD8-AG8 -> -0.00019874754 | AI8: =AG8*100/AD8 -> 113.82779
A9: Zhang et al., | B9: Microplastic pollution in water, sediment, and fish from artificial reefs around the Ma’an Archipelago, Shengsi, China - ScienceDirect | C9: 30.775 | D9: 122.641 | E9: Fibers | F9: 92% fibers | G9: -1.27 | H9: 50 | I9: 27.6 | J9: =LOG(I9, 10) - (G9) * LOG(H9,10)^(G9+1) -> 2.5415701 | K9: =-1*10^J9*(G9+1) -> 93.958018 | L9: =IF(E9="Fragments",0.000000097*K9*(5000^(4+G9)-1)/(4+G9),0.000106*K9*(5000^(2+G9)-1)/(2+G9)) -> 6.8280714 | M9: 2018 | N9: 5 | O9: 75 | P9: 59111.205 | Q9: 25.3 | R9: 0.61037441 | S9: 0.13007918 | T9: 0.65010635 | U9: 6000 | V9: =L9*R9*0.000000001 -> 4.1676801e-09 | W9: =V9*N9 -> 2.08384e-08 | X9: =M9-1950 -> 68 | Y9: =N9/S9 -> 38.438126 | Z9: =S9*X9 -> 8.8453843 | AA9: =IF(N9<Z9,W9/(1-(1-N9/Z9)^3),W9)*10000 -> 0.0002270378 | AB9: =N9/T9 -> 7.6910493 | AC9: =T9*X9 -> 44.207232 | AD9: =IF(N9<AC9,W9/(1-(1-N9/AC9)^3),W9)*10000 -> 0.00068914486 | AE9: =2021-1950 -> 71 | AF9: {=_xlfn.IFS(N9<=AC9,W9*(3/(X9^3 - (X9-AB9)^3)),N9>AC9,W9*(3/X9^3))} -> 6.5751405e-13 | AG9: =(AF9/3)*(AE9^3)*10000 -> 0.00078443837 | AH9: =AD9-AG9 -> -9.5293511e-05 | AI9: =AG9*100/AD9 -> 113.82779
A10: Zhang et al., | B10: Microplastic pollution in water, sediment, and fish from artificial reefs around the Ma’an Archipelago, Shengsi, China - ScienceDirect | C10: 30.771 | D10: 122.733 | E10: Fibers | F10: 92% fibers | G10: -1.27 | H10: 50 | I10: 73.6 | J10: =LOG(I10, 10) - (G10) * LOG(H10,10)^(G10+1) -> 2.9675388 | K10: =-1*10^J10*(G10+1) -> 250.55472 | L10: =IF(E10="Fragments",0.000000097*K10*(5000^(4+G10)-1)/(4+G10),0.000106*K10*(5000^(2+G10)-1)/(2+G10)) -> 18.20819 | M10: 2018 | N10: 5 | O10: 75 | P10: 68236.186 | Q10: 33.6 | R10: 0.61037441 | S10: 0.12900196 | T10: 0.66525852 | U10: 3000 | V10: =L10*R10*0.000000001 -> 1.1113813e-08 | W10: =V10*N10 -> 5.5569067e-08 | X10: =M10-1950 -> 68 | Y10: =N10/S10 -> 38.759102 | Z10: =S10*X10 -> 8.7721331 | AA10: =IF(N10<Z10,W10/(1-(1-N10/Z10)^3),W10)*10000 -> 0.00060369291 | AB10: =N10/T10 -> 7.5158751 | AC10: =T10*X10 -> 45.23758 | AD10: =IF(N10<AC10,W10/(1-(1-N10/AC10)^3),W10)*10000 -> 0.0018755343 | AE10: =2021-1950 -> 71 | AF10: {=_xlfn.IFS(N10<=AC10,W10*(3/(X10^3 - (X10-AB10)^3)),N10>AC10,W10*(3/X10^3))} -> 1.7894498e-12 | AG10: =(AF10/3)*(AE10^3)*10000 -> 0.0021348792 | AH10: =AD10-AG10 -> -0.00025934496 | AI10: =AG10*100/AD10 -> 113.82779
A11: Zhang et al., | B11: Microplastic pollution in water, sediment, and fish from artificial reefs around the Ma’an Archipelago, Shengsi, China - ScienceDirect | C11: 30.762 | D11: 122.659 | E11: Fibers | F11: 92% fibers | G11: -1.27 | H11: 50 | I11: 73.6 | J11: =LOG(I11, 10) - (G11) * LOG(H11,10)^(G11+1) -> 2.9675388 | K11: =-1*10^J11*(G11+1) -> 250.55472 | L11: =IF(E11="Fragments",0.000000097*K11*(5000^(4+G11)-1)/(4+G11),0.000106*K11*(5000^(2+G11)-1)/(2+G11)) -> 18.20819 | M11: 2018 | N11: 5 | O11: 75 | P11: 61718.342 | Q11: 40.1 | R11: 0.61037441 | S11: 0.12816458 | T11: 0.65010635 | U11: 7000 | V11: =L11*R11*0.000000001 -> 1.1113813e-08 | W11: =V11*N11 -> 5.5569067e-08 | X11: =M11-1950 -> 68 | Y11: =N11/S11 -> 39.012339 | Z11: =S11*X11 -> 8.7151914 | AA11: =IF(N11<Z11,W11/(1-(1-N11/Z11)^3),W11)*10000 -> 0.00060235271 | AB11: =N11/T11 -> 7.6910493 | AC11: =T11*X11 -> 44.207232 | AD11: =IF(N11<AC11,W11/(1-(1-N11/AC11)^3),W11)*10000 -> 0.0018377196 | AE11: =2021-1950 -> 71 | AF11: {=_xlfn.IFS(N11<=AC11,W11*(3/(X11^3 - (X11-AB11)^3)),N11>AC11,W11*(3/X11^3))} -> 1.7533708e-12 | AG11: =(AF11/3)*(AE11^3)*10000 -> 0.0020918356 | AH11: =AD11-AG11 -> -0.00025411603 | AI11: =AG11*100/AD11 -> 113.82779
A12: Chen et al., | B12: Assessment of microplastics derived from mariculture in Xiangshan Bay, China - ScienceDirect | C12: 29.5 | D12: 121.51 | E12: Fibers | F12: 82% fibers | G12: -1.14 | H12: 500 | I12: 109.9629 | J12: =LOG(I12, 10) - (G12) * LOG(H12,10)^(G12+1) -> 3.0333043 | K12: =-1*10^J12*(G12+1) -> 151.15842 | L12: =IF(E12="Fragments",0.000000097*K12*(5000^(4+G12)-1)/(4+G12),0.000106*K12*(5000^(2+G12)-1)/(2+G12)) -> 28.253202 | M12: 2017 | N12: 5 | O12: 6 | P12: 3701.4912 | R12: 0.61037441 | S12: 0.13341858 | T12: 0.587512 | U12: 1000 | V12: =L12*R12*0.000000001 -> 1.7245032e-08 | W12: =V12*N12 -> 8.6225158e-08 | X12: =M12-1950 -> 67 | Y12: =N12/S12 -> 37.476038 | Z12: =S12*X12 -> 8.9390452 | AA12: =IF(N12<Z12,W12/(1-(1-N12/Z12)^3),W12)*10000 -> 0.00094293438 | AB12: =N12/T12 -> 8.5104644 | AC12: =T12*X12 -> 39.363304 | AD12: =IF(N12<AC12,W12/(1-(1-N12/AC12)^3),W12)*10000 -> 0.002576105 | AE12: =2021-1950 -> 71 | AF12: {=_xlfn.IFS(N12<=AC12,W12*(3/(X12^3 - (X12-AB12)^3)),N12>AC12,W12*(3/X12^3))} -> 2.5695697e-12 | AG12: =(AF12/3)*(AE12^3)*10000 -> 0.0030655909 | AH12: =AD12-AG12 -> -0.00048948589 | AI12: =AG12*100/AD12 -> 119.00101
